<?xml version="1.0"?>
<robot xmlns:xacro="http://www.ros.org/wiki/xacro">
    
    <!-- Include external Xacro file -->
    <xacro:include filename="frame.xacro"/>
    <xacro:include filename="wheels.xacro"/>
    
    <!-- Use the create_link macro from the included file -->
    <xacro:create_link link_name="frame" length="${link_length}"/>
    
    <!-- Create another link -->
    <xacro:create_link link_name="wheels" length="2.0"/>
    
    <!-- Define a joint between link1 and link2 -->
    <joint name="joint1" type="revolute">
        <parent link="link1"/>
        <child link="link2"/>
        <origin xyz="1.0 0 0"/>
        <axis xyz="0 0 1"/>
        <limit lower="0" upper="1.57" effort="100" velocity="1.0"/>
    </joint>

</robot>