<?xml version="1.0" ?>
<!-- =================================================================================== -->
<!-- |    This document was autogenerated by xacro from frame_gearbox_wheel_joint.xacro | -->
<!-- |    EDITING THIS FILE BY HAND IS NOT RECOMMENDED                                 | -->
<!-- =================================================================================== -->
<robot name="frame_jointed">
  <!--check_urdf just_work.urdf-->
  <!--for all resolute joints: <limit effort="100" velocity="1.0" lower="-1.57" upper="1.57"/>-->
  <!--###########  Fast Changes  ###########-->
  <!--<xacro:macro name="gearbox_link" params="prefix width length height origin_xyz origin_rpy mass ixx ixy ixz iyy iyz izz material rgba">
	    <link name="${prefix}_gearbox">
		
		<inertial>
		    <origin xyz="${origin_xyz}" rpy="${origin_rpy}"/>
		    <mass value="${mass}"/>
		    <inertia 
		        ixx="${ixx}"  
		        ixy="${ixy}"  
		        ixz="${ixz}" 
		        iyy="${iyy}" 
		        iyz="${iyz}" 
		        izz="${izz}"/>
		</inertial>
		
		<visual>
		    <origin xyz="${origin_xyz}" rpy="${origin_rpy}"/>
		    <geometry>
		        <box size="${width} ${length} ${height}"/>
		    </geometry>
		    <material name="${material}">
		        <color rgba="${rgba}"/>
		    </material>
		</visual>

		<collision>
		    <origin xyz="${origin_xyz}" rpy="${origin_rpy}"/>
		    <geometry>
		        <box size="${width} ${length} ${height}"/>
		    </geometry>
		    <material name="${material}">
		        <color rgba="${rgba}"/>
		    </material>
		</collision>

	    </link>
	</xacro:macro>-->
  <!--###########  ALL LINKS  ###########-->
  <link name="whole_frame">
    <!-- Inertial properties -->
    <inertial>
      <origin rpy="0 0 0" xyz="0 0 0.2"/>
      <mass value="5"/>
      <inertia ixx="0.108" ixy="0" ixz="0" iyy="0.24" iyz="0" izz="0.417"/>
    </inertial>
    <!-- Visual properties -->
    <visual>
      <origin rpy="0 0 0" xyz="0 0 0.2"/>
      <geometry>
        <box size="0.5 0.75 0.09999999999999998"/>
      </geometry>
      <material name="aluminum">
        <color rgba="0.5 0.5 0.5 1.0"/>
      </material>
    </visual>
    <!-- Collision properties (no material/color) -->
    <collision>
      <origin rpy="0 0 0" xyz="0 0 0.2"/>
      <geometry>
        <box size="0.5 0.75 0.09999999999999998"/>
      </geometry>
    </collision>
  </link>
  <!--mass ixx ixy ixz iyy iyz izz-->
  <link name="front_left_gearbox">
    <!-- Inertial properties -->
    <!--<inertial>
		    <origin xyz="${origin_xyz}" rpy="${origin_rpy}"/>
		    <mass value="${mass}"/>
		    <inertia 
		        ixx="${ixx}"  
		        ixy="${ixy}"  
		        ixz="${ixz}" 
		        iyy="${iyy}" 
		        iyz="${iyz}" 
		        izz="${izz}"/>
		</inertial> -->
    <!-- Visual properties -->
    <visual>
      <origin rpy="0 0 0" xyz="0.28125  0.1875  0.05"/>
      <geometry>
        <box size="0.125 0.1875 0.15000000000000002"/>
      </geometry>
      <material name="aluminum">
        <color rgba="0.5 0.5 0.5 1.0"/>
      </material>
    </visual>
    <!-- Collision properties (no material/color needed here) -->
    <collision>
      <origin rpy="0 0 0" xyz="0.28125  0.1875  0.05"/>
      <geometry>
        <box size="0.125 0.1875 0.15000000000000002"/>
      </geometry>
    </collision>
  </link>
  <!--mass="${gear_mass}" 
        ixx="${gear_mass}" 
        ixy="${gear_mass}" 
        ixz="${gear_mass}" 
        iyy="${gear_mass}" 
        iyz="${gear_mass}" 
        izz="${gear_mass}"-->
  <!--mass ixx ixy ixz iyy iyz izz-->
  <link name="front_right_gearbox">
    <!-- Inertial properties -->
    <!--<inertial>
		    <origin xyz="${origin_xyz}" rpy="${origin_rpy}"/>
		    <mass value="${mass}"/>
		    <inertia 
		        ixx="${ixx}"  
		        ixy="${ixy}"  
		        ixz="${ixz}" 
		        iyy="${iyy}" 
		        iyz="${iyz}" 
		        izz="${izz}"/>
		</inertial> -->
    <!-- Visual properties -->
    <visual>
      <origin rpy="0 0 0" xyz="0.28125  -0.1875 0.05"/>
      <geometry>
        <box size="0.125 0.1875 0.15000000000000002"/>
      </geometry>
      <material name="aluminum">
        <color rgba="0.5 0.5 0.5 1.0"/>
      </material>
    </visual>
    <!-- Collision properties (no material/color needed here) -->
    <collision>
      <origin rpy="0 0 0" xyz="0.28125  -0.1875 0.05"/>
      <geometry>
        <box size="0.125 0.1875 0.15000000000000002"/>
      </geometry>
    </collision>
  </link>
  <!--mass="${gear_mass}" 
        ixx="${gear_mass}" 
        ixy="${gear_mass}" 
        ixz="${gear_mass}" 
        iyy="${gear_mass}" 
        iyz="${gear_mass}" 
        izz="${gear_mass}"-->
  <!--mass ixx ixy ixz iyy iyz izz-->
  <link name="back_left_gearbox">
    <!-- Inertial properties -->
    <!--<inertial>
		    <origin xyz="${origin_xyz}" rpy="${origin_rpy}"/>
		    <mass value="${mass}"/>
		    <inertia 
		        ixx="${ixx}"  
		        ixy="${ixy}"  
		        ixz="${ixz}" 
		        iyy="${iyy}" 
		        iyz="${iyz}" 
		        izz="${izz}"/>
		</inertial> -->
    <!-- Visual properties -->
    <visual>
      <origin rpy="0 0 0" xyz="-0.28125 0.1875  0.05"/>
      <geometry>
        <box size="0.125 0.1875 0.15000000000000002"/>
      </geometry>
      <material name="aluminum">
        <color rgba="0.5 0.5 0.5 1.0"/>
      </material>
    </visual>
    <!-- Collision properties (no material/color needed here) -->
    <collision>
      <origin rpy="0 0 0" xyz="-0.28125 0.1875  0.05"/>
      <geometry>
        <box size="0.125 0.1875 0.15000000000000002"/>
      </geometry>
    </collision>
  </link>
  <!--mass="${gear_mass}" 
        ixx="${gear_mass}" 
        ixy="${gear_mass}" 
        ixz="${gear_mass}" 
        iyy="${gear_mass}" 
        iyz="${gear_mass}" 
        izz="${gear_mass}"-->
  <!--mass ixx ixy ixz iyy iyz izz-->
  <link name="back_right_gearbox">
    <!-- Inertial properties -->
    <!--<inertial>
		    <origin xyz="${origin_xyz}" rpy="${origin_rpy}"/>
		    <mass value="${mass}"/>
		    <inertia 
		        ixx="${ixx}"  
		        ixy="${ixy}"  
		        ixz="${ixz}" 
		        iyy="${iyy}" 
		        iyz="${iyz}" 
		        izz="${izz}"/>
		</inertial> -->
    <!-- Visual properties -->
    <visual>
      <origin rpy="0 0 0" xyz="-0.28125 -0.1875 0.05"/>
      <geometry>
        <box size="0.125 0.1875 0.15000000000000002"/>
      </geometry>
      <material name="aluminum">
        <color rgba="0.5 0.5 0.5 1.0"/>
      </material>
    </visual>
    <!-- Collision properties (no material/color needed here) -->
    <collision>
      <origin rpy="0 0 0" xyz="-0.28125 -0.1875 0.05"/>
      <geometry>
        <box size="0.125 0.1875 0.15000000000000002"/>
      </geometry>
    </collision>
  </link>
  <!--mass="${gear_mass}" 
        ixx="${gear_mass}" 
        ixy="${gear_mass}" 
        ixz="${gear_mass}" 
        iyy="${gear_mass}" 
        iyz="${gear_mass}" 
        izz="${gear_mass}"-->
  <link name="front_left_wheel">
    <!-- Inertial properties -->
    <inertial>
      <origin rpy="0 0 0" xyz="0.28125 0.325 0.1"/>
      <mass value="0.1"/>
      <inertia ixx="0.00196" ixy="0.00196" ixz="0.00196" iyy="0.00196" iyz="0.00196" izz="0.00196"/>
    </inertial>
    <!-- Visual properties -->
    <visual>
      <origin rpy="0 0 0" xyz="0.28125 0.325 0.1"/>
      <geometry>
        <cylinder length="0.15" radius="0.1"/>
      </geometry>
      <material name="plastic">
        <color rgba="0 0 0 1"/>
      </material>
    </visual>
    <!-- Collision properties (no material/color needed) -->
    <collision>
      <origin rpy="0 0 0" xyz="0.28125 0.325 0.1"/>
      <geometry>
        <cylinder length="0.15" radius="0.1"/>
      </geometry>
    </collision>
  </link>
  <link name="front_right_wheel">
    <!-- Inertial properties -->
    <inertial>
      <origin rpy="0 0 0" xyz="0.28125 -0.325 0.1"/>
      <mass value="0.1"/>
      <inertia ixx="0.00196" ixy="0.00196" ixz="0.00196" iyy="0.00196" iyz="0.00196" izz="0.00196"/>
    </inertial>
    <!-- Visual properties -->
    <visual>
      <origin rpy="0 0 0" xyz="0.28125 -0.325 0.1"/>
      <geometry>
        <cylinder length="0.15" radius="0.1"/>
      </geometry>
      <material name="plastic">
        <color rgba="0 0 0 1"/>
      </material>
    </visual>
    <!-- Collision properties (no material/color needed) -->
    <collision>
      <origin rpy="0 0 0" xyz="0.28125 -0.325 0.1"/>
      <geometry>
        <cylinder length="0.15" radius="0.1"/>
      </geometry>
    </collision>
  </link>
  <link name="back_left_wheel">
    <!-- Inertial properties -->
    <inertial>
      <origin rpy="0 0 0" xyz="-0.28125 0.325 0.1"/>
      <mass value="0.1"/>
      <inertia ixx="0.00196" ixy="0.00196" ixz="0.00196" iyy="0.00196" iyz="0.00196" izz="0.00196"/>
    </inertial>
    <!-- Visual properties -->
    <visual>
      <origin rpy="0 0 0" xyz="-0.28125 0.325 0.1"/>
      <geometry>
        <cylinder length="0.15" radius="0.1"/>
      </geometry>
      <material name="plastic">
        <color rgba="0 0 0 1"/>
      </material>
    </visual>
    <!-- Collision properties (no material/color needed) -->
    <collision>
      <origin rpy="0 0 0" xyz="-0.28125 0.325 0.1"/>
      <geometry>
        <cylinder length="0.15" radius="0.1"/>
      </geometry>
    </collision>
  </link>
  <link name="back_right_wheel">
    <!-- Inertial properties -->
    <inertial>
      <origin rpy="0 0 0" xyz="-0.28125 -0.325 0.1"/>
      <mass value="0.1"/>
      <inertia ixx="0.00196" ixy="0.00196" ixz="0.00196" iyy="0.00196" iyz="0.00196" izz="0.00196"/>
    </inertial>
    <!-- Visual properties -->
    <visual>
      <origin rpy="0 0 0" xyz="-0.28125 -0.325 0.1"/>
      <geometry>
        <cylinder length="0.15" radius="0.1"/>
      </geometry>
      <material name="plastic">
        <color rgba="0 0 0 1"/>
      </material>
    </visual>
    <!-- Collision properties (no material/color needed) -->
    <collision>
      <origin rpy="0 0 0" xyz="-0.28125 -0.325 0.1"/>
      <geometry>
        <cylinder length="0.15" radius="0.1"/>
      </geometry>
    </collision>
  </link>
  <!--###########  ALL JOINTS (stinky since legalization) ###########-->
  <!--Gearbox to Frame Joints-->
  <joint name="front_left_gearbox_frame_joint" type="fixed">
    <parent link="whole_frame"/>
    <child link="front_left_gearbox"/>
    <origin rpy="0 0 0" xyz="0.28125  0.1875  0.2"/>
  </joint>
  <joint name="front_right_gearbox_frame_joint" type="fixed">
    <parent link="whole_frame"/>
    <child link="front_right_gearbox"/>
    <origin rpy="0 0 0" xyz="0.28125 -0.1875  0.2"/>
  </joint>
  <joint name="back_left_gearbox_frame_joint" type="fixed">
    <parent link="whole_frame"/>
    <child link="back_left_gearbox"/>
    <origin rpy="0 0 0" xyz="-0.28125 0.1875 0.2"/>
  </joint>
  <joint name="back_right_gearbox_frame_joint" type="fixed">
    <parent link="whole_frame"/>
    <child link="back_right_gearbox"/>
    <origin rpy="0 0 0" xyz="-0.28125  -0.1875 0.2"/>
  </joint>
  <!--Gearbox to Wheels Joints-->
  <joint name="front_left_wheel_joint" type="continuous">
    <parent link="front_left_gearbox"/>
    <child link="front_left_wheel"/>
    <origin rpy="0 0 0" xyz="0.28125  0.25  0.1"/>
    <axis xyz="0 0 1"/>
  </joint>
  <joint name="front_right_wheel_joint" type="continuous">
    <parent link="front_right_gearbox"/>
    <child link="front_right_wheel"/>
    <origin rpy="0 0 0" xyz="0.28125 -0.25  0.1"/>
    <axis xyz="0 0 1"/>
  </joint>
  <joint name="back_left_wheel_joint" type="continuous">
    <parent link="back_left_gearbox"/>
    <child link="back_left_wheel"/>
    <origin rpy="0 0 0" xyz="-0.28125 0.25 0.1"/>
    <axis xyz="0 0 1"/>
  </joint>
  <joint name="back_right_wheel_joint" type="continuous">
    <parent link="back_right_gearbox"/>
    <child link="back_right_wheel"/>
    <origin rpy="0 0 0" xyz="-0.28125  -0.25 0.1"/>
    <axis xyz="0 0 1"/>
  </joint>
  <!-- Dummy link to avoid root link inertia issue -->
  <link name="base_link"/>
  <joint name="base_frame_link" type="fixed">
    <parent link="base_link"/>
    <child link="whole_frame"/>
    <origin rpy="0 0 0" xyz="0 0 0"/>
  </joint>
</robot>
